Workbook
Name FCAMB: Fatores!$G$36
Name _Toc112831755: UC!$B$13
Name ITEC: Fatores!$E$22
Name PTA: Atores!$D$10
Name Atores: Atores!$B$13:$C$17
Name CUC: UC!$D$13:$D$38
Name FCTEC: Fatores!$E$22
Name UC: UC!$A$12:$C$38
Name PTUC: UC!$D$10

Sheet Geral
B3: Estimativa de Esforço de Projeto baseado em Pontos de Caso de Uso (vs 1.1)
B6: Projeto: | D6: Casar
B7: Responsável: | D7: Gabriel Carneiro Roque Toti Silva
B8: Data: | D8: 45908 | F8: Vs. do Documento: | H8: 1.0
D9: < Obs.: As instruções para uso da planilha encontram-se logo a baixo>
B12: Resultado da Estimativa | G12: Esforço por fases | J12: Horas | K12: %
B13: Total de Pontos de Caso de Uso(tamanho) | E13: =Atores!D10+UC!D10 -> 108 | G13: Fase de Prospecção | J13: =$E$13*$E$14*K13 -> 15.12 | K13: =dadoshistoricos!E31 -> 0.046666667
B14: Homens/hora por PCU | E14: =dadoshistoricos!L30 -> 3 | G14: Fase de Análise | J14: =$E$13*$E$14*K14 -> 53.28 | K14: =dadoshistoricos!F31*0.8 -> 0.16444444
G15: Fase de Projeto | J15: =$E$13*$E$14*K15 -> 13.32 | K15: =dadoshistoricos!F31*0.2 -> 0.041111111
G16: Fase de Planejamento | J16: =$E$13*$E$14*K16 -> 21.6 | K16: =dadoshistoricos!G31 -> 0.066666667
G17: Fase de Desenvolvimento | J17: =$E$13*$E$14*K17 -> 180 | K17: =dadoshistoricos!H31 -> 0.55555556
G18: Processo de Monitoramento e Controle | J18: =$E$13*$E$14*K18 -> 7.2 | K18: =dadoshistoricos!I31 -> 0.022222222
G19: Fase de Fechamento | J19: =$E$13*$E$14*K19 -> 21.96 | K19: =dadoshistoricos!J31 -> 0.067777778
B20: Instruções para realizar a estimativa do Projeto: | G20: Processo Controle de mudanças | J20: =$E$13*$E$14*K20 -> 11.52 | K20: =dadoshistoricos!K31 -> 0.035555556
G21: Total de horas do Projeto | J21: =SUM(J13:J19) -> 312.48 | K21: =SUM(K13:K20) -> 1
B22: 1) Preencha a Planilha Atores indicando os atores(usuários do sistema) e a sua complexidade.
B23: 2) Preencha a Planilha UC indicando os casos de uso e quantidade de transações.
B24: 3) Preencha a Planilha Fatores, com os fatores de complexidade ambiental e técnicos do Projeto.
B25: 4) Após a execução dos passos anteriores, os resultados finais encontram-se na Planilha Geral.
B27: Obs.:
B28: Existem informações ocultas na células que possuem marcação(pontos coloridos). Posicione o mouse sobre a celula para visualizar a informação.

Sheet Atores
B1: Atores do Projeto
B6: Complexidade do Ator | C6: Peso | D6: Qt. de Atores | E6: Descrição
B7: Simples | C7: 1 | D7: =COUNTIF(Atores,B7) -> 2 | E7: Ator interage com o sistema através de uma API
B8: Médio | C8: 2 | D8: =COUNTIF(Atores,B8) -> 0 | E8: Ator interage com o sistema através de um Protocolo de Comunicação.
B9: Complexo | C9: 3 | D9: =COUNTIF(Atores,B9) -> 2 | E9: Ator interage com o sistema através de uma Interface
C10: Peso Total Atores = | D10: =(C7*D7)+(C8*D8)+(C9*D9) -> 8
B13: Atores | C13: Complexidade
B14: Usuário Representante | C14: Complexo
B15: Usuário Comum | C15: Complexo
B16: Sistema de Autenticação Social | C16: Simples
B17: Sistema de Notificação | C17: Simples
B19: Encryption Key Manager | C19: Simples
B20: Gateway de Pagamentos | C20: Simples
B21: Total | C21: =SUBTOTAL(103,C14:C20) -> 6

Sheet UC
B2: Casos de Uso do Projeto
B6: Complexidade do Caso de Uso | C6: Peso | D6: Qt. de UC | E6: Descrição
B7: Simples | C7: 5 | D7: =COUNTIF(CUC,B7) -> 18 | E7: Utiliza apenas uma entidade no banco de dados
B8: Médio | C8: 10 | D8: =COUNTIF(CUC,B8) -> 1 | E8: Utiliza duas entidades no banco de dados.
B9: Complexo | C9: 15 | D9: =COUNTIF(CUC,B9) -> 0 | E9: Utiliza 3 ou mais entidades no banco de dados.
C10: Peso Total UC | D10: =(C7*D7)+(C8*D8)+(C9*D9) -> 100
A12: ID | B12: Nome do RFC ou RFS | C12: Nro Entidades | D12: Complexidade | E12: Discriminar Transações(opcional)
B13: [RFS01] Cadastrar Usuário | C13: 1 | D13: =IF(C13<4,"Simples",(IF(C13>7,"Complexo",IF(C13="", "","Médio")))) -> Simples | E13: Usuario | O13: 1
B14: [RFS02] Editar Usuário | C14: 1 | D14: =IF(C14<4,"Simples",(IF(C14>7,"Complexo",IF(C14="", " ","Médio")))) -> Simples | E14: Usuario | O14: 2
B15: [RFS03] Excluir Usuário | C15: 3 | D15: =IF(C15<4,"Simples",(IF(C15>7,"Complexo",IF(C15="", "","Médio")))) -> Simples | E15: Usuario, Imóvel e Anúncio | O15: 3
B16: [RFS04] Cadastrar Preferências | C16: 2 | D16: =IF(C16<4,"Simples",(IF(C16>7,"Complexo",IF(C16="", "","Médio")))) -> Simples | E16: Usuário e Preferências | O16: 4
B17: [RFS05] Editar Preferências | C17: 1 | D17: =IF(C17<4,"Simples",(IF(C17>7,"Complexo",IF(C17="", "","Médio")))) -> Simples | E17: Preferências | O17: 5
B18: [RFS06] Excluir Preferências | C18: 1 | D18: =IF(C18<4,"Simples",(IF(C18>7,"Complexo",IF(C18="", "","Médio")))) -> Simples | E18: Preferências | O18: 6
B19: [RFS07] Gerar compatibilização automática | C19: 4 | D19: =IF(C19<4,"Simples",(IF(C19>7,"Complexo",IF(C19="", "","Médio")))) -> Médio | E19: Usuário, Imóvel, Preferências, Anúncios | O19: 7
B20: [RFS08] Cadastrar Imóvel | C20: 3 | D20: =IF(C20<4,"Simples",(IF(C20>7,"Complexo",IF(C20="", "","Médio")))) -> Simples | E20: Usuário, Imóvel, Preferências | O20: 8
B21: [RFS09] Consultar Imóvel | C21: 3 | D21: =IF(C21<4,"Simples",(IF(C21>7,"Complexo",IF(C21="", "","Médio")))) -> Simples | E21: Usuário, Imóvel, Preferências | O21: 9
B22: [RFS10] Editar Imóvel | C22: 1 | D22: =IF(C22<4,"Simples",(IF(C22>7,"Complexo",IF(C22="", "","Médio")))) -> Simples | E22: Imóvel | O22: 10
B23: [RFS11] Excluir Imóvel | C23: 3 | D23: =IF(C23<4,"Simples",(IF(C23>7,"Complexo",IF(C23="", "","Médio")))) -> Simples | E23: Usuário, Imóvel, Anúncio | O23: 11
B24: [RFS12] Cadastrar Anúncio | C24: 2 | D24: =IF(C24<4,"Simples",(IF(C24>7,"Complexo",IF(C24="", "","Médio")))) -> Simples | E24: Imóvel, Anúncio | O24: 12
B25: [RFS13] Consultar Anúncio | C25: 2 | D25: =IF(C25<4,"Simples",(IF(C25>7,"Complexo",IF(C25="", "","Médio")))) -> Simples | E25: Imóvel, Anúncio | O25: 13
B26: [RFS14] Editar Anúncio | C26: 2 | D26: =IF(C26<4,"Simples",(IF(C26>7,"Complexo",IF(C26="", "","Médio")))) -> Simples | E26: Imóvel, Anúncio | O26: 14
... B31: [RFS19] Formulário de Pagamento | C31: 1 | D31: =IF(C31<4,"Simples",(IF(C31>7,"Complexo",IF(C31="", "","Médio")))) -> Simples | E31: Usuário | O31: 21
O32: 22
O33: 23
O34: 24
O35: 25
O36: 26
O37: 27
O38: 28
A39: Total | B39: =SUBTOTAL(103,B13:B38) -> 19 | O39: 29
O40: 30
O41: 31
O42: 32
O43: 33
O44: 34
O45: 35
O46: 36
O47: 37
O48: 38
O49: 39
...

Sheet Fatores
B4: Fatores de Complexidade
B7: Influência Tecnológica
B8: ID | C8: Descrição | D8: Peso | E8: Influência
B9: T01 | C9: Sistemas Distribuídos | D9: 2 | E9: 0
B10: T02 | C10: Tempo de resposta | D10: 1 | E10: 4
B11: T03 | C11: Grau de escolaridade do usuário final | D11: 1 | E11: 0
B12: T04 | C12: Processamento interno complexo | D12: 1 | E12: 1
B13: T05 | C13: Reusabilidade do código em outras aplicações | D13: 1 | E13: 0
B14: T06 | C14: Facilidade de instalação | D14: 0.5 | E14: 5
B15: T07 | C15: Usabilidade (facilidade operacional) | D15: 0.5 | E15: 5
B16: T08 | C16: Portabilidade | D16: 2 | E16: 3
B17: T09 | C17: Facilidade de manutenção | D17: 1 | E17: 1
B18: T10 | C18: Concorrência | D18: 1 | E18: 0
B19: T11 | C19: Características especiais de segurança | D19: 1 | E19: 2
B20: T12 | C20: Acesso direto para terceiros | D20: 1 | E20: 0
B21: T13 | C21: Facilidades especiais de treinamento | D21: 1 | E21: 2
B22: Fator de Complexidade Técnica | E22: =0.6+(0.01*SUM(D9*E9,D10*E10,D11*E11,D12*E12,D13*E13,D14*E14,D15*E15,D16*E16,D17*E17,D18*E18,D19*E19,D20*E20,D21*E21)) -> 0.81
B26: Influência Ambiental
B27: ID | C27: Descrição | F27: Peso | G27: Influência
B28: F01 | C28: Familiaridade com o Processo de Desenvolvimento de Software | F28: 1.5 | G28: 4
B29: F02 | C29: Experiência na Aplicação | F29: 0.5 | G29: 5
B30: F03 | C30: Experiência em Programação Orientada a Objetos | F30: 1 | G30: 4
B31: F04 | C31: Capacidade do Líder de Projeto | F31: 0.5 | G31: 2
B32: F05 | C32: Motivação | F32: 1 | G32: 1
B33: F06 | C33: Requisitos estáveis | F33: 2 | G33: 3
B34: F07 | C34: Trabalhadores com dedicação parcial | F34: -1 | G34: 5
B35: F08 | C35: Dificuldade da Linguagem de Programação | F35: -1 | G35: 0
B36: Fator de Complexidade Ambiental | G36: =1.4+(-0.03*SUM(F28*G28,F29*G29,F30*G30,F31*G31,F32*G32,F33*G33,F34*G34,F35*G35)) -> 0.935

Sheet dadoshistoricos
B1: Base histórica de Projetos
B5: Projetos | C5: Tamanho | D5: Horas Reais | E5: Prospecção | F5: Análise e Projeto | G5: Planejamento | H5: Desenvolvimento | I5: Fechamento | J5: Mon.Controle | K5: Cont. Mud. | L5: Produtividade
B6: Projeto 01 | C6: 190 | D6: =SUM(E6:K6) -> 589 | E6: 25 | F6: 80 | G6: 25 | H6: 400 | I6: 10 | J6: 25 | K6: 24 | L6: =D6/C6 -> 3.1
B7: Projeto 02 | C7: 130 | D7: =SUM(E7:K7) -> 326 | E7: 20 | F7: 120 | G7: 30 | H7: 100 | I7: 10 | J7: 30 | K7: 16 | L7: =D7/C7 -> 2.5076923
B8: Projeto 03 | C8: 140 | D8: =SUM(E8:K8) -> 399 | E8: 17 | F8: 90 | G8: 32 | H8: 200 | I8: 12 | J8: 32 | K8: 16 | L8: =D8/C8 -> 2.85
B9: Projeto 04 | C9: 125 | D9: =SUM(E9:K9) -> 486 | E9: 22 | F9: 80 | G9: 33 | H9: 300 | I9: 8 | J9: 35 | K9: 8 | L9: =D9/C9 -> 3.888
B29: Total de horas por fase | D29: =SUM(D6:D28) -> 1800 | E29: =SUM(E6:E28) -> 84 | F29: =SUM(F6:F28) -> 370 | G29: =SUM(G6:G28) -> 120 | H29: =SUM(H6:H28) -> 1000 | I29: =SUM(I6:I28) -> 40 | J29: =SUM(J6:J28) -> 122 | K29: =SUM(K6:K28) -> 64
J30: Produtividade média | L30: 3
B31: % de esforço por fases | E31: =(E29*1)/$D$29 -> 0.046666667 | F31: =(F29*1)/$D$29 -> 0.20555556 | G31: =(G29*1)/$D$29 -> 0.066666667 | H31: =(H29*1)/$D$29 -> 0.55555556 | I31: =(I29*1)/$D$29 -> 0.022222222 | J31: =(J29*1)/$D$29 -> 0.067777778 | K31: =(K29*1)/$D$29 -> 0.035555556 | L31: =SUM(E31:K31) -> 1

Sheet Cronograma
A1: ID | B1: Atividade | C1: Trabalho Estimado | D1: Duração Estimada | E1: Duração Real | F1: Predessessor | G1: Recursos | H1: Status
A2: 1 | B2: Prospecção | C2: 16 | D2: 4
A3: 2 | B3: Análise | C3: 56 | D3: 14 | F3: 1 | I3: =PRODUCT(DIVIDE(Geral!$J$17,$J$43),J3) -> 13.090909 | J3: 16
A4: 3 | B4: Projeto | C4: 14 | D4: 3 | F4: 2 | I4: =PRODUCT(DIVIDE(Geral!$J$17,$J$43),J4) -> 4.0909091 | J4: 5
A5: 4 | B5: Planejamento | C5: 22 | D5: 6 | F5: 3 | I5: =PRODUCT(DIVIDE(Geral!$J$17,$J$43),J5) -> 6.5454545 | J5: 8
A6: 5 | B6: Implementar RFS01 | C6: =(Atores!$D$10 + IF(EQ(UC!D13,"Simples"),5, IF(EQ(UC!D13,"Média"),10,15))) * Fatores!$E$22 * Fatores!$G$36 * dadoshistoricos!$H$31 -> 5.46975 | D6: 4 | F6: 4 | I6: =PRODUCT(DIVIDE(Geral!$J$17,$J$43),J6) -> 4.9090909 | J6: 6
A7: 6 | B7: Implementar RFS02 | C7: =(Atores!$D$10 + IF(EQ(UC!D14,"Simples"),5, IF(EQ(UC!D14,"Média"),10,15))) * Fatores!$E$22 * Fatores!$G$36 * dadoshistoricos!$H$31 -> 5.46975 | D7: 1 | F7: 5 | I7: =PRODUCT(DIVIDE(Geral!$J$17,$J$43),J7) -> 4.0909091 | J7: 5
A8: 7 | B8: Implementar RFS03 | C8: =(Atores!$D$10 + IF(EQ(UC!D15,"Simples"),5, IF(EQ(UC!D15,"Média"),10,15))) * Fatores!$E$22 * Fatores!$G$36 * dadoshistoricos!$H$31 -> 5.46975 | D8: 2 | F8: 5 | I8: =PRODUCT(DIVIDE(Geral!$J$17,$J$43),J8) -> 4.0909091 | J8: 5
A9: 8 | B9: Implementar RFS04 | C9: =(Atores!$D$10 + IF(EQ(UC!D16,"Simples"),5, IF(EQ(UC!D16,"Média"),10,15))) * Fatores!$E$22 * Fatores!$G$36 * dadoshistoricos!$H$31 -> 5.46975 | D9: 1 | F9: 5 | I9: =PRODUCT(DIVIDE(Geral!$J$17,$J$43),J9) -> 4.0909091 | J9: 5
A10: 9 | B10: Implementar RFS05 | C10: =(Atores!$D$10 + IF(EQ(UC!D17,"Simples"),5, IF(EQ(UC!D17,"Média"),10,15))) * Fatores!$E$22 * Fatores!$G$36 * dadoshistoricos!$H$31 -> 5.46975 | D10: 1 | F10: 8 | I10: =PRODUCT(DIVIDE(Geral!$J$17,$J$43),J10) -> 4.0909091 | J10: 5
A11: 10 | B11: Implementar RFS06 | C11: =(Atores!$D$10 + IF(EQ(UC!D18,"Simples"),5, IF(EQ(UC!D18,"Média"),10,15))) * Fatores!$E$22 * Fatores!$G$36 * dadoshistoricos!$H$31 -> 5.46975 | D11: 1 | F11: 8 | I11: =PRODUCT(DIVIDE(Geral!$J$17,$J$43),J11) -> 4.0909091 | J11: 5
A12: 11 | B12: Implementar RFS08 | C12: =(Atores!$D$10 + IF(EQ(UC!D19,"Simples"),5, IF(EQ(UC!D19,"Média"),10,15))) * Fatores!$E$22 * Fatores!$G$36 * dadoshistoricos!$H$31 -> 9.67725 | D12: 1 | F12: 5 | I12: =PRODUCT(DIVIDE(Geral!$J$17,$J$43),J12) -> 4.0909091 | J12: 5
A13: 12 | B13: Implementar RFS09 | C13: =(Atores!$D$10 + IF(EQ(UC!D20,"Simples"),5, IF(EQ(UC!D20,"Média"),10,15))) * Fatores!$E$22 * Fatores!$G$36 * dadoshistoricos!$H$31 -> 5.46975 | D13: 1 | F13: 11 | I13: =PRODUCT(DIVIDE(Geral!$J$17,$J$43),J13) -> 4.0909091 | J13: 5
A14: 13 | B14: Implementar RFS10 | C14: =(Atores!$D$10 + IF(EQ(UC!D21,"Simples"),5, IF(EQ(UC!D21,"Média"),10,15))) * Fatores!$E$22 * Fatores!$G$36 * dadoshistoricos!$H$31 -> 5.46975 | D14: 1 | F14: 11 | I14: =PRODUCT(DIVIDE(Geral!$J$17,$J$43),J14) -> 4.0909091 | J14: 5
A15: 14 | B15: Implementar RFS11 | C15: =(Atores!$D$10 + IF(EQ(UC!D22,"Simples"),5, IF(EQ(UC!D22,"Média"),10,15))) * Fatores!$E$22 * Fatores!$G$36 * dadoshistoricos!$H$31 -> 5.46975 | D15: 1 | F15: 11 | I15: =PRODUCT(DIVIDE(Geral!$J$17,$J$43),J15) -> 4.0909091 | J15: 5
A16: 15 | B16: Implementar RFS12 | C16: =(Atores!$D$10 + IF(EQ(UC!D23,"Simples"),5, IF(EQ(UC!D23,"Média"),10,15))) * Fatores!$E$22 * Fatores!$G$36 * dadoshistoricos!$H$31 -> 5.46975 | D16: 1 | F16: 12 | I16: =PRODUCT(DIVIDE(Geral!$J$17,$J$43),J16) -> 4.0909091 | J16: 5
A17: 16 | B17: Implementar RFS13 | C17: =(Atores!$D$10 + IF(EQ(UC!D24,"Simples"),5, IF(EQ(UC!D24,"Média"),10,15))) * Fatores!$E$22 * Fatores!$G$36 * dadoshistoricos!$H$31 -> 5.46975 | D17: 1 | F17: 15 | I17: =PRODUCT(DIVIDE(Geral!$J$17,$J$43),J17) -> 8.1818182 | J17: 10
... A19: 18 | B19: Implementar RFS15 | C19: =(Atores!$D$10 + IF(EQ(UC!D26,"Simples"),5, IF(EQ(UC!D26,"Média"),10,15))) * Fatores!$E$22 * Fatores!$G$36 * dadoshistoricos!$H$31 -> 5.46975 | D19: 1 | F19: 15 | I19: =PRODUCT(DIVIDE(Geral!$J$17,$J$43),J19) -> 4.0909091 | J19: 5
A20: 19 | B20: Implementar RFS07 | C20: =(Atores!$D$10 + IF(EQ(UC!D27,"Simples"),5, IF(EQ(UC!D27,"Média"),10,15))) * Fatores!$E$22 * Fatores!$G$36 * dadoshistoricos!$H$31 -> 5.46975 | D20: 2 | F20: 5;8.11;14 | I20: =PRODUCT(DIVIDE(Geral!$J$17,$J$43),J20) -> 4.0909091 | J20: 5
A21: 20 | B21: Implementar RFS16 | C21: =(Atores!$D$10 + IF(EQ(UC!D28,"Simples"),5, IF(EQ(UC!D28,"Média"),10,15))) * Fatores!$E$22 * Fatores!$G$36 * dadoshistoricos!$H$31 -> 5.46975 | D21: 1 | F21: 19 | I21: =PRODUCT(DIVIDE(Geral!$J$17,$J$43),J21) -> 4.0909091 | J21: 5
A22: 21 | B22: Implementar RFS17 | C22: =(Atores!$D$10 + IF(EQ(UC!D29,"Simples"),5, IF(EQ(UC!D29,"Média"),10,15))) * Fatores!$E$22 * Fatores!$G$36 * dadoshistoricos!$H$31 -> 5.46975 | D22: 1 | F22: 20 | I22: =PRODUCT(DIVIDE(Geral!$J$17,$J$43),J22) -> 4.0909091 | J22: 5
A23: 22 | B23: Implementar RFS18 | C23: =(Atores!$D$10 + IF(EQ(UC!D30,"Simples"),5, IF(EQ(UC!D30,"Média"),10,15))) * Fatores!$E$22 * Fatores!$G$36 * dadoshistoricos!$H$31 -> 5.46975 | D23: 1 | F23: 21 | I23: =PRODUCT(DIVIDE(Geral!$J$17,$J$43),J23) -> 4.0909091 | J23: 5
A24: 23 | B24: Implementar RFS19 | C24: =(Atores!$D$10 + IF(EQ(#REF!,"Simples"),5, IF(EQ(#REF!,"Média"),10,15))) * Fatores!$E$22 * Fatores!$G$36 * dadoshistoricos!$H$31 -> #REF! | D24: 1 | F24: 6 | I24: =PRODUCT(DIVIDE(Geral!$J$17,$J$43),J24) -> 4.0909091 | J24: 5
A25: 24 | B25: Implementar RFS20 | C25: =(Atores!$D$10 + IF(EQ(UC!D31,"Simples"),5, IF(EQ(UC!D31,"Média"),10,15))) * Fatores!$E$22 * Fatores!$G$36 * dadoshistoricos!$H$31 -> 5.46975 | D25: 1 | F25: 4 | I25: =PRODUCT(DIVIDE(Geral!$J$17,$J$43),J25) -> 4.0909091 | J25: 5
A26: 25 | B26: Testar RFS01 | C26: =(Atores!$D$10 + IF(EQ(UC!D13,"Simples"),5, IF(EQ(UC!D32,"Média"),10,15))) * Fatores!$E$22 * Fatores!$G$36 * dadoshistoricos!$H$31 -> 5.46975 | D26: 1 | F26: 5 | I26: =PRODUCT(DIVIDE(Geral!$J$17,$J$43),J26) -> 4.0909091 | J26: 5
A27: 26 | B27: Testar RFS02 | C27: =(Atores!$D$10 + IF(EQ(UC!D14,"Simples"),5, IF(EQ(UC!D33,"Média"),10,15))) * Fatores!$E$22 * Fatores!$G$36 * dadoshistoricos!$H$31 -> 5.46975 | D27: 1 | F27: 6 | I27: =PRODUCT(DIVIDE(Geral!$J$17,$J$43),J27) -> 4.0909091 | J27: 5
A28: 27 | B28: Testar RFS03 | C28: =(Atores!$D$10 + IF(EQ(UC!D15,"Simples"),5, IF(EQ(UC!D34,"Média"),10,15))) * Fatores!$E$22 * Fatores!$G$36 * dadoshistoricos!$H$31 -> 5.46975 | D28: 1 | F28: 7 | I28: =PRODUCT(DIVIDE(Geral!$J$17,$J$43),J28) -> 4.0909091 | J28: 5
A29: 28 | B29: Testar RFS04 | C29: =(Atores!$D$10 + IF(EQ(UC!D16,"Simples"),5, IF(EQ(UC!D35,"Média"),10,15))) * Fatores!$E$22 * Fatores!$G$36 * dadoshistoricos!$H$31 -> 5.46975 | D29: 1 | F29: 8 | I29: =PRODUCT(DIVIDE(Geral!$J$17,$J$43),J29) -> 4.0909091 | J29: 5
A30: 29 | B30: Testar RFS05 | C30: =(Atores!$D$10 + IF(EQ(UC!D17,"Simples"),5, IF(EQ(UC!D36,"Média"),10,15))) * Fatores!$E$22 * Fatores!$G$36 * dadoshistoricos!$H$31 -> 5.46975 | D30: 1 | F30: 9 | I30: =PRODUCT(DIVIDE(Geral!$J$17,$J$43),J30) -> 4.0909091 | J30: 5
A31: 30 | B31: Testar RFS06 | C31: =(Atores!$D$10 + IF(EQ(UC!D18,"Simples"),5, IF(EQ(UC!D37,"Média"),10,15))) * Fatores!$E$22 * Fatores!$G$36 * dadoshistoricos!$H$31 -> 5.46975 | D31: 1 | F31: 10 | I31: =PRODUCT(DIVIDE(Geral!$J$17,$J$43),J31) -> 4.0909091 | J31: 5
A32: 31 | B32: Testar RFS07 | C32: =(Atores!$D$10 + IF(EQ(UC!D19,"Simples"),5, IF(EQ(UC!D38,"Média"),10,15))) * Fatores!$E$22 * Fatores!$G$36 * dadoshistoricos!$H$31 -> 9.67725 | D32: 1 | F32: 19 | I32: =PRODUCT(DIVIDE(Geral!$J$17,$J$43),J32) -> 4.0909091 | J32: 5
A33: 32 | B33: Testar RFS08 | C33: =(Atores!$D$10 + IF(EQ(UC!D20,"Simples"),5, IF(EQ(UC!D39,"Média"),10,15))) * Fatores!$E$22 * Fatores!$G$36 * dadoshistoricos!$H$31 -> 5.46975 | D33: 1 | F33: 11 | I33: =PRODUCT(DIVIDE(Geral!$J$17,$J$43),J33) -> 4.0909091 | J33: 5
A34: 33 | B34: Testar RFS09 | C34: =(Atores!$D$10 + IF(EQ(UC!D21,"Simples"),5, IF(EQ(UC!D40,"Média"),10,15))) * Fatores!$E$22 * Fatores!$G$36 * dadoshistoricos!$H$31 -> 5.46975 | D34: 1 | F34: 12 | I34: =PRODUCT(DIVIDE(Geral!$J$17,$J$43),J34) -> 4.0909091 | J34: 5
A35: 34 | B35: Testar RFS10 | C35: =(Atores!$D$10 + IF(EQ(UC!D22,"Simples"),5, IF(EQ(UC!D41,"Média"),10,15))) * Fatores!$E$22 * Fatores!$G$36 * dadoshistoricos!$H$31 -> 5.46975 | D35: 1 | F35: 13 | I35: =PRODUCT(DIVIDE(Geral!$J$17,$J$43),J35) -> 4.0909091 | J35: 5
A36: 35 | B36: Testar RFS11 | C36: =(Atores!$D$10 + IF(EQ(UC!D23,"Simples"),5, IF(EQ(UC!D42,"Média"),10,15))) * Fatores!$E$22 * Fatores!$G$36 * dadoshistoricos!$H$31 -> 5.46975 | D36: 1 | F36: 14 | I36: =PRODUCT(DIVIDE(Geral!$J$17,$J$43),J36) -> 4.0909091 | J36: 5
A37: 36 | B37: Testar RFS12 | C37: =(Atores!$D$10 + IF(EQ(UC!D24,"Simples"),5, IF(EQ(UC!D43,"Média"),10,15))) * Fatores!$E$22 * Fatores!$G$36 * dadoshistoricos!$H$31 -> 5.46975 | D37: 1 | F37: 15 | I37: =PRODUCT(DIVIDE(Geral!$J$17,$J$43),J37) -> 4.0909091 | J37: 5
... A42: 41 | B42: Testar RFS17 | C42: =(Atores!$D$10 + IF(EQ(UC!D29,"Simples"),5, IF(EQ(UC!D48,"Média"),10,15))) * Fatores!$E$22 * Fatores!$G$36 * dadoshistoricos!$H$31 -> 5.46975 | D42: 1 | F42: 21 | I42: =PRODUCT(DIVIDE(Geral!$J$17,$J$43),J42) -> 4.0909091 | J42: 5
A43: 42 | B43: Testar RFS18 | C43: =(Atores!$D$10 + IF(EQ(UC!D30,"Simples"),5, IF(EQ(UC!D49,"Média"),10,15))) * Fatores!$E$22 * Fatores!$G$36 * dadoshistoricos!$H$31 -> 5.46975 | D43: 1 | F43: 22 | J43: =SUM(J3:J42) -> 220
A44: 44 | B44: Testar RFS19 | C44: =(Atores!$D$10 + IF(EQ(UC!D31,"Simples"),5, IF(EQ(UC!D51,"Média"),10,15))) * Fatores!$E$22 * Fatores!$G$36 * dadoshistoricos!$H$31 -> 5.46975 | D44: 1 | F44: 24
